Workbook

Sheet FR_Coverage_Detail
A1: FR_ID | B1: Section | C1: Dominant Dimension | D1: Primary Actor/Owner | E1: Atomic Functional Requirement | F1: Mapped UC IDs | G1: UC Count | H1: Mapped BR IDs | I1: BR Count | J1: Mapped WF IDs | K1: WF Count | L1: Has UC | M1: Has BR | N1: Has WF | O1: Covered by Any | P1: Overlap Category | Q1: Review
A2: HM-FR-001 | B2: 3.1 | C2: Interaction | D2: Student | E2: Student submits hostel accommodation request through the system. | F2: HM-UC-010 | G2: 1 | H2: BR-HM-111 | I2: 1 | J2: HM-WF-103 | K2: 1 | L2: =IF(G2>0,1,0) -> 1 | M2: =IF(I2>0,1,0) -> 1 | N2: =IF(K2>0,1,0) -> 1 | O2: =IF(OR(L2=1,M2=1,N2=1),1,0) -> 1 | P2: =IF(O2=0,"Uncovered",_xlfn.TEXTJOIN(" + ",TRUE,IF(L2=1,"UC",""),IF(M2=1,"BR",""),IF(N2=1,"WF",""))) -> UC + BR + WF
A3: HM-FR-002 | B3: 3.1 | C3: Behavior | D3: System | E3: System records and manages hostel accommodation application details and application status. | F3: HM-UC-010 | G3: 1 | I3: 0 | J3: HM-WF-103 | K3: 1 | L3: =IF(G3>0,1,0) -> 1 | M3: =IF(I3>0,1,0) -> 0 | N3: =IF(K3>0,1,0) -> 1 | O3: =IF(OR(L3=1,M3=1,N3=1),1,0) -> 1 | P3: =IF(O3=0,"Uncovered",_xlfn.TEXTJOIN(" + ",TRUE,IF(L3=1,"UC",""),IF(M3=1,"BR",""),IF(N3=1,"WF",""))) -> UC + WF
A4: HM-FR-003 | B4: 3.1 | C4: Interaction | D4: Super Admin | E4: Super Admin performs hostel and room allotment decisions in batch-oriented institutional processes. | F4: HM-UC-011 | G4: 1 | H4: BR-HM-113 | I4: 1 | J4: HM-WF-103 | K4: 1 | L4: =IF(G4>0,1,0) -> 1 | M4: =IF(I4>0,1,0) -> 1 | N4: =IF(K4>0,1,0) -> 1 | O4: =IF(OR(L4=1,M4=1,N4=1),1,0) -> 1 | P4: =IF(O4=0,"Uncovered",_xlfn.TEXTJOIN(" + ",TRUE,IF(L4=1,"UC",""),IF(M4=1,"BR",""),IF(N4=1,"WF",""))) -> UC + BR + WF
A5: HM-FR-004 | B5: 3.1 | C5: Interaction | D5: Super Admin | E5: Super Admin performs centrally controlled room re-allotments where required. | F5: HM-UC-011 | G5: 1 | H5: BR-HM-113 | I5: 1 | J5: HM-WF-103 | K5: 1 | L5: =IF(G5>0,1,0) -> 1 | M5: =IF(I5>0,1,0) -> 1 | N5: =IF(K5>0,1,0) -> 1 | O5: =IF(OR(L5=1,M5=1,N5=1),1,0) -> 1 | P5: =IF(O5=0,"Uncovered",_xlfn.TEXTJOIN(" + ",TRUE,IF(L5=1,"UC",""),IF(M5=1,"BR",""),IF(N5=1,"WF",""))) -> UC + BR + WF
A6: HM-FR-005 | B6: 3.1 | C6: Interaction | D6: Super Admin | E6: Super Admin performs formal room-vacation updates that change institutional hostel occupancy records. | F6: HM-UC-029, HM-UC-030, HM-UC-031 | G6: 3 | H6: BR-HM-015, BR-HM-028 | I6: 2 | J6: HM-WF-109 | K6: 1 | L6: =IF(G6>0,1,0) -> 1 | M6: =IF(I6>0,1,0) -> 1 | N6: =IF(K6>0,1,0) -> 1 | O6: =IF(OR(L6=1,M6=1,N6=1),1,0) -> 1 | P6: =IF(O6=0,"Uncovered",_xlfn.TEXTJOIN(" + ",TRUE,IF(L6=1,"UC",""),IF(M6=1,"BR",""),IF(N6=1,"WF",""))) -> UC + BR + WF
A7: HM-FR-006 | B7: 3.1 | C7: Constraint | D7: System | E7: System maintains room assignment history for audit, traceability, and review. | F7: HM-UC-012 | G7: 1 | I7: 0 | J7: HM-WF-103 | K7: 1 | L7: =IF(G7>0,1,0) -> 1 | M7: =IF(I7>0,1,0) -> 0 | N7: =IF(K7>0,1,0) -> 1 | O7: =IF(OR(L7=1,M7=1,N7=1),1,0) -> 1 | P7: =IF(O7=0,"Uncovered",_xlfn.TEXTJOIN(" + ",TRUE,IF(L7=1,"UC",""),IF(M7=1,"BR",""),IF(N7=1,"WF",""))) -> UC + WF
A8: HM-FR-007 | B8: 3.1 | C8: Interaction | D8: Student | E8: Student views current room allocation information permitted to the student. | F8: HM-UC-042 | G8: 1 | H8: BR-HM-012 | I8: 1 | J8: HM-WF-103 | K8: 1 | L8: =IF(G8>0,1,0) -> 1 | M8: =IF(I8>0,1,0) -> 1 | N8: =IF(K8>0,1,0) -> 1 | O8: =IF(OR(L8=1,M8=1,N8=1),1,0) -> 1 | P8: =IF(O8=0,"Uncovered",_xlfn.TEXTJOIN(" + ",TRUE,IF(L8=1,"UC",""),IF(M8=1,"BR",""),IF(N8=1,"WF",""))) -> UC + BR + WF
A9: HM-FR-008 | B9: 3.1 | C9: Interaction | D9: Student | E9: Student views historical room allocation information permitted to the student. | F9: HM-UC-042 | G9: 1 | H9: BR-HM-012 | I9: 1 | J9: HM-WF-103 | K9: 1 | L9: =IF(G9>0,1,0) -> 1 | M9: =IF(I9>0,1,0) -> 1 | N9: =IF(K9>0,1,0) -> 1 | O9: =IF(OR(L9=1,M9=1,N9=1),1,0) -> 1 | P9: =IF(O9=0,"Uncovered",_xlfn.TEXTJOIN(" + ",TRUE,IF(L9=1,"UC",""),IF(M9=1,"BR",""),IF(N9=1,"WF",""))) -> UC + BR + WF
A10: HM-FR-009 | B10: 3.2 | C10: Interaction | D10: Caretaker | E10: Caretaker maintains hostel-level room availability information. | F10: HM-UC-015 | G10: 1 | I10: 0 | J10: HM-WF-104 | K10: 1 | L10: =IF(G10>0,1,0) -> 1 | M10: =IF(I10>0,1,0) -> 0 | N10: =IF(K10>0,1,0) -> 1 | O10: =IF(OR(L10=1,M10=1,N10=1),1,0) -> 1 | P10: =IF(O10=0,"Uncovered",_xlfn.TEXTJOIN(" + ",TRUE,IF(L10=1,"UC",""),IF(M10=1,"BR",""),IF(N10=1,"WF",""))) -> UC + WF
A11: HM-FR-010 | B11: 3.2 | C11: Interaction | D11: Caretaker | E11: Caretaker maintains hostel-level room occupancy information. | F11: HM-UC-015 | G11: 1 | I11: 0 | J11: HM-WF-104 | K11: 1 | L11: =IF(G11>0,1,0) -> 1 | M11: =IF(I11>0,1,0) -> 0 | N11: =IF(K11>0,1,0) -> 1 | O11: =IF(OR(L11=1,M11=1,N11=1),1,0) -> 1 | P11: =IF(O11=0,"Uncovered",_xlfn.TEXTJOIN(" + ",TRUE,IF(L11=1,"UC",""),IF(M11=1,"BR",""),IF(N11=1,"WF",""))) -> UC + WF
A12: HM-FR-011 | B12: 3.2 | C12: Behavior | D12: System | E12: System updates room occupancy based on approved allotments, re-allotments, vacations, and authorized individual exchanges. | F12: HM-UC-015, HM-UC-031 | G12: 2 | H12: BR-HM-117, BR-HM-023 | I12: 2 | J12: HM-WF-104, HM-WF-109 | K12: 2 | L12: =IF(G12>0,1,0) -> 1 | M12: =IF(I12>0,1,0) -> 1 | N12: =IF(K12>0,1,0) -> 1 | O12: =IF(OR(L12=1,M12=1,N12=1),1,0) -> 1 | P12: =IF(O12=0,"Uncovered",_xlfn.TEXTJOIN(" + ",TRUE,IF(L12=1,"UC",""),IF(M12=1,"BR",""),IF(N12=1,"WF",""))) -> UC + BR + WF
A13: HM-FR-012 | B13: 3.2 | C13: Interaction | D13: Caretaker | E13: Caretaker handles individual room exchange operations within authorized hostel-level scope and policy limits. | F13: HM-UC-013, HM-UC-014 | G13: 2 | H13: BR-HM-115, BR-HM-116 | I13: 2 | J13: HM-WF-104 | K13: 1 | L13: =IF(G13>0,1,0) -> 1 | M13: =IF(I13>0,1,0) -> 1 | N13: =IF(K13>0,1,0) -> 1 | O13: =IF(OR(L13=1,M13=1,N13=1),1,0) -> 1 | P13: =IF(O13=0,"Uncovered",_xlfn.TEXTJOIN(" + ",TRUE,IF(L13=1,"UC",""),IF(M13=1,"BR",""),IF(N13=1,"WF",""))) -> UC + BR + WF
A14: HM-FR-013 | B14: 3.2 | C14: Interaction | D14: Warden | E14: Warden reviews room assignments and occupancy patterns for planning, discipline, and compliance. | F14: HM-UC-014 | G14: 1 | H14: BR-HM-116 | I14: 1 | J14: HM-WF-104 | K14: 1 | L14: =IF(G14>0,1,0) -> 1 | M14: =IF(I14>0,1,0) -> 1 | N14: =IF(K14>0,1,0) -> 1 | O14: =IF(OR(L14=1,M14=1,N14=1),1,0) -> 1 | P14: =IF(O14=0,"Uncovered",_xlfn.TEXTJOIN(" + ",TRUE,IF(L14=1,"UC",""),IF(M14=1,"BR",""),IF(N14=1,"WF",""))) -> UC + BR + WF
A15: HM-FR-014 | B15: 3.2 | C15: Constraint | D15: System | E15: System prevents room occupancy from exceeding defined room capacity. | G15: 0 | H15: BR-HM-112 | I15: 1 | J15: HM-WF-103 | K15: 1 | L15: =IF(G15>0,1,0) -> 0 | M15: =IF(I15>0,1,0) -> 1 | N15: =IF(K15>0,1,0) -> 1 | O15: =IF(OR(L15=1,M15=1,N15=1),1,0) -> 1 | P15: =IF(O15=0,"Uncovered",_xlfn.TEXTJOIN(" + ",TRUE,IF(L15=1,"UC",""),IF(M15=1,"BR",""),IF(N15=1,"WF",""))) -> BR + WF | Q15: Added UC - HM-UC-015.UC015 is also relevant to the FR
A16: HM-FR-015 | B16: 3.2 | C16: Behavior | D16: System | E16: System maintains up-to-date room status information needed for hostel operations. | F16: HM-UC-015, HM-UC-031 | G16: 2 | H16: BR-HM-117, BR-HM-023 | I16: 2 | J16: HM-WF-104, HM-WF-109 | K16: 2 | L16: =IF(G16>0,1,0) -> 1 | M16: =IF(I16>0,1,0) -> 1 | N16: =IF(K16>0,1,0) -> 1 | O16: =IF(OR(L16=1,M16=1,N16=1),1,0) -> 1 | P16: =IF(O16=0,"Uncovered",_xlfn.TEXTJOIN(" + ",TRUE,IF(L16=1,"UC",""),IF(M16=1,"BR",""),IF(N16=1,"WF",""))) -> UC + BR + WF
A17: HM-FR-016 | B17: 3.3 | C17: Interaction | D17: Caretaker | E17: Caretaker records student attendance according to hostel operational practice. | F17: HM-UC-043 | G17: 1 | I17: 0 | K17: 0 | L17: =IF(G17>0,1,0) -> 1 | M17: =IF(I17>0,1,0) -> 0 | N17: =IF(K17>0,1,0) -> 0 | O17: =IF(OR(L17=1,M17=1,N17=1),1,0) -> 1 | P17: =IF(O17=0,"Uncovered",_xlfn.TEXTJOIN(" + ",TRUE,IF(L17=1,"UC",""),IF(M17=1,"BR",""),IF(N17=1,"WF",""))) -> UC
A18: HM-FR-017 | B18: 3.3 | C18: Interaction | D18: Caretaker | E18: Caretaker monitors student attendance according to hostel operational practice. | F18: HM-UC-043 | G18: 1 | I18: 0 | K18: 0 | L18: =IF(G18>0,1,0) -> 1 | M18: =IF(I18>0,1,0) -> 0 | N18: =IF(K18>0,1,0) -> 0 | O18: =IF(OR(L18=1,M18=1,N18=1),1,0) -> 1 | P18: =IF(O18=0,"Uncovered",_xlfn.TEXTJOIN(" + ",TRUE,IF(L18=1,"UC",""),IF(M18=1,"BR",""),IF(N18=1,"WF",""))) -> UC | Q18: Added UC - HM-WF-101.WF-101 is also relevant to the FR
A19: HM-FR-018 | B19: 3.3 | C19: Behavior | D19: System | E19: System links attendance information with leave decisions where applicable. | F19: HM-UC-004 | G19: 1 | H19: BR-HM-105 | I19: 1 | J19: HM-WF-101 | K19: 1 | L19: =IF(G19>0,1,0) -> 1 | M19: =IF(I19>0,1,0) -> 1 | N19: =IF(K19>0,1,0) -> 1 | O19: =IF(OR(L19=1,M19=1,N19=1),1,0) -> 1 | P19: =IF(O19=0,"Uncovered",_xlfn.TEXTJOIN(" + ",TRUE,IF(L19=1,"UC",""),IF(M19=1,"BR",""),IF(N19=1,"WF",""))) -> UC + BR + WF
A20: HM-FR-019 | B20: 3.3 | C20: Behavior | D20: System | E20: System supports disciplinary review using attendance information where applicable. | F20: HM-UC-043 | G20: 1 | I20: 0 | K20: 0 | L20: =IF(G20>0,1,0) -> 1 | M20: =IF(I20>0,1,0) -> 0 | N20: =IF(K20>0,1,0) -> 0 | O20: =IF(OR(L20=1,M20=1,N20=1),1,0) -> 1 | P20: =IF(O20=0,"Uncovered",_xlfn.TEXTJOIN(" + ",TRUE,IF(L20=1,"UC",""),IF(M20=1,"BR",""),IF(N20=1,"WF",""))) -> UC
A21: HM-FR-020 | B21: 3.3 | C21: Interaction | D21: Warden | E21: Warden views attendance summaries, trends, and exceptions for oversight. | F21: HM-UC-043 | G21: 1 | I21: 0 | K21: 0 | L21: =IF(G21>0,1,0) -> 1 | M21: =IF(I21>0,1,0) -> 0 | N21: =IF(K21>0,1,0) -> 0 | O21: =IF(OR(L21=1,M21=1,N21=1),1,0) -> 1 | P21: =IF(O21=0,"Uncovered",_xlfn.TEXTJOIN(" + ",TRUE,IF(L21=1,"UC",""),IF(M21=1,"BR",""),IF(N21=1,"WF",""))) -> UC
A22: HM-FR-021 | B22: 3.3 | C22: Constraint | D22: System | E22: System retains attendance records for reporting, monitoring, and compliance purposes. | F22: HM-UC-043 | G22: 1 | I22: 0 | K22: 0 | L22: =IF(G22>0,1,0) -> 1 | M22: =IF(I22>0,1,0) -> 0 | N22: =IF(K22>0,1,0) -> 0 | O22: =IF(OR(L22=1,M22=1,N22=1),1,0) -> 1 | P22: =IF(O22=0,"Uncovered",_xlfn.TEXTJOIN(" + ",TRUE,IF(L22=1,"UC",""),IF(M22=1,"BR",""),IF(N22=1,"WF",""))) -> UC
A23: HM-FR-022 | B23: 3.4 | C23: Interaction | D23: Student | E23: Student submits leave request with required supporting information or documents. | F23: HM-UC-001 | G23: 1 | H23: BR-HM-101, BR-HM-102, BR-HM-103, BR-HM-022 | I23: 4 | J23: HM-WF-101 | K23: 1 | L23: =IF(G23>0,1,0) -> 1 | M23: =IF(I23>0,1,0) -> 1 | N23: =IF(K23>0,1,0) -> 1 | O23: =IF(OR(L23=1,M23=1,N23=1),1,0) -> 1 | P23: =IF(O23=0,"Uncovered",_xlfn.TEXTJOIN(" + ",TRUE,IF(L23=1,"UC",""),IF(M23=1,"BR",""),IF(N23=1,"WF",""))) -> UC + BR + WF
A24: HM-FR-023 | B24: 3.4 | C24: Interaction | D24: Caretaker | E24: Caretaker approves leave request according to hostel policy. | F24: HM-UC-002 | G24: 1 | H24: BR-HM-104 | I24: 1 | J24: HM-WF-101 | K24: 1 | L24: =IF(G24>0,1,0) -> 1 | M24: =IF(I24>0,1,0) -> 1 | N24: =IF(K24>0,1,0) -> 1 | O24: =IF(OR(L24=1,M24=1,N24=1),1,0) -> 1 | P24: =IF(O24=0,"Uncovered",_xlfn.TEXTJOIN(" + ",TRUE,IF(L24=1,"UC",""),IF(M24=1,"BR",""),IF(N24=1,"WF",""))) -> UC + BR + WF
A25: HM-FR-024 | B25: 3.4 | C25: Interaction | D25: Caretaker | E25: Caretaker rejects leave request according to hostel policy. | F25: HM-UC-002 | G25: 1 | H25: BR-HM-104 | I25: 1 | J25: HM-WF-101 | K25: 1 | L25: =IF(G25>0,1,0) -> 1 | M25: =IF(I25>0,1,0) -> 1 | N25: =IF(K25>0,1,0) -> 1 | O25: =IF(OR(L25=1,M25=1,N25=1),1,0) -> 1 | P25: =IF(O25=0,"Uncovered",_xlfn.TEXTJOIN(" + ",TRUE,IF(L25=1,"UC",""),IF(M25=1,"BR",""),IF(N25=1,"WF",""))) -> UC + BR + WF
A26: HM-FR-025 | B26: 3.4 | C26: Behavior | D26: System | E26: System issues status updates to the student for submitted leave requests. | F26: HM-UC-003, HM-UC-004 | G26: 2 | I26: 0 | J26: HM-WF-101 | K26: 1 | L26: =IF(G26>0,1,0) -> 1 | M26: =IF(I26>0,1,0) -> 0 | N26: =IF(K26>0,1,0) -> 1 | O26: =IF(OR(L26=1,M26=1,N26=1),1,0) -> 1 | P26: =IF(O26=0,"Uncovered",_xlfn.TEXTJOIN(" + ",TRUE,IF(L26=1,"UC",""),IF(M26=1,"BR",""),IF(N26=1,"WF",""))) -> UC + WF
A27: HM-FR-026 | B27: 3.4 | C27: Behavior | D27: System | E27: System links leave records with attendance where applicable. | F27: HM-UC-004 | G27: 1 | H27: BR-HM-105 | I27: 1 | J27: HM-WF-101 | K27: 1 | L27: =IF(G27>0,1,0) -> 1 | M27: =IF(I27>0,1,0) -> 1 | N27: =IF(K27>0,1,0) -> 1 | O27: =IF(OR(L27=1,M27=1,N27=1),1,0) -> 1 | P27: =IF(O27=0,"Uncovered",_xlfn.TEXTJOIN(" + ",TRUE,IF(L27=1,"UC",""),IF(M27=1,"BR",""),IF(N27=1,"WF",""))) -> UC + BR + WF
A28: HM-FR-027 | B28: 3.4 | C28: Behavior | D28: System | E28: System makes leave records available to support security or supervisory planning. | F28: HM-UC-002 | G28: 1 | I28: 0 | J28: HM-WF-101 | K28: 1 | L28: =IF(G28>0,1,0) -> 1 | M28: =IF(I28>0,1,0) -> 0 | N28: =IF(K28>0,1,0) -> 1 | O28: =IF(OR(L28=1,M28=1,N28=1),1,0) -> 1 | P28: =IF(O28=0,"Uncovered",_xlfn.TEXTJOIN(" + ",TRUE,IF(L28=1,"UC",""),IF(M28=1,"BR",""),IF(N28=1,"WF",""))) -> UC + WF
A29: HM-FR-028 | B29: 3.4 | C29: Constraint | D29: System | E29: System retains leave history for audit, review, and reporting. | F29: HM-UC-003 | G29: 1 | I29: 0 | J29: HM-WF-101 | K29: 1 | L29: =IF(G29>0,1,0) -> 1 | M29: =IF(I29>0,1,0) -> 0 | N29: =IF(K29>0,1,0) -> 1 | O29: =IF(OR(L29=1,M29=1,N29=1),1,0) -> 1 | P29: =IF(O29=0,"Uncovered",_xlfn.TEXTJOIN(" + ",TRUE,IF(L29=1,"UC",""),IF(M29=1,"BR",""),IF(N29=1,"WF",""))) -> UC + WF
A30: HM-FR-029 | B30: 3.5 | C30: Interaction | D30: Student | E30: Student submits complaint related to hostel facilities, services, infrastructure, or operational issues. | F30: HM-UC-006 | G30: 1 | H30: BR-HM-106, BR-HM-022 | I30: 2 | J30: HM-WF-102 | K30: 1 | L30: =IF(G30>0,1,0) -> 1 | M30: =IF(I30>0,1,0) -> 1 | N30: =IF(K30>0,1,0) -> 1 | O30: =IF(OR(L30=1,M30=1,N30=1),1,0) -> 1 | P30: =IF(O30=0,"Uncovered",_xlfn.TEXTJOIN(" + ",TRUE,IF(L30=1,"UC",""),IF(M30=1,"BR",""),IF(N30=1,"WF",""))) -> UC + BR + WF
A31: HM-FR-030 | B31: 3.5 | C31: Behavior | D31: System | E31: System records complaint category, description, and optional attachment support where applicable. | F31: HM-UC-006 | G31: 1 | H31: BR-HM-107 | I31: 1 | J31: HM-WF-102 | K31: 1 | L31: =IF(G31>0,1,0) -> 1 | M31: =IF(I31>0,1,0) -> 1 | N31: =IF(K31>0,1,0) -> 1 | O31: =IF(OR(L31=1,M31=1,N31=1),1,0) -> 1 | P31: =IF(O31=0,"Uncovered",_xlfn.TEXTJOIN(" + ",TRUE,IF(L31=1,"UC",""),IF(M31=1,"BR",""),IF(N31=1,"WF",""))) -> UC + BR + WF | Q31: Inappropiate mapping of UC
A32: HM-FR-031 | B32: 3.5 | C32: Interaction | D32: Caretaker | E32: Caretaker reviews complaint within operational authority. | F32: HM-UC-007 | G32: 1 | H32: BR-HM-107 | I32: 1 | J32: HM-WF-102 | K32: 1 | L32: =IF(G32>0,1,0) -> 1 | M32: =IF(I32>0,1,0) -> 1 | N32: =IF(K32>0,1,0) -> 1 | O32: =IF(OR(L32=1,M32=1,N32=1),1,0) -> 1 | P32: =IF(O32=0,"Uncovered",_xlfn.TEXTJOIN(" + ",TRUE,IF(L32=1,"UC",""),IF(M32=1,"BR",""),IF(N32=1,"WF",""))) -> UC + BR + WF
A33: HM-FR-032 | B33: 3.5 | C33: Interaction | D33: Caretaker | E33: Caretaker addresses complaint within operational authority. | F33: HM-UC-007 | G33: 1 | H33: BR-HM-108 | I33: 1 | J33: HM-WF-102 | K33: 1 | L33: =IF(G33>0,1,0) -> 1 | M33: =IF(I33>0,1,0) -> 1 | N33: =IF(K33>0,1,0) -> 1 | O33: =IF(OR(L33=1,M33=1,N33=1),1,0) -> 1 | P33: =IF(O33=0,"Uncovered",_xlfn.TEXTJOIN(" + ",TRUE,IF(L33=1,"UC",""),IF(M33=1,"BR",""),IF(N33=1,"WF",""))) -> UC + BR + WF
A34: HM-FR-033 | B34: 3.5 | C34: Interaction | D34: Caretaker | E34: Caretaker updates complaint status within operational authority. | F34: HM-UC-007 | G34: 1 | H34: BR-HM-108 | I34: 1 | J34: HM-WF-102 | K34: 1 | L34: =IF(G34>0,1,0) -> 1 | M34: =IF(I34>0,1,0) -> 1 | N34: =IF(K34>0,1,0) -> 1 | O34: =IF(OR(L34=1,M34=1,N34=1),1,0) -> 1 | P34: =IF(O34=0,"Uncovered",_xlfn.TEXTJOIN(" + ",TRUE,IF(L34=1,"UC",""),IF(M34=1,"BR",""),IF(N34=1,"WF",""))) -> UC + BR + WF
A35: HM-FR-034 | B35: 3.5 | C35: Interaction | D35: Warden | E35: Warden monitors unresolved, delayed, or escalated complaints. | F35: HM-UC-008 | G35: 1 | H35: BR-HM-109, BR-HM-110 | I35: 2 | J35: HM-WF-102 | K35: 1 | L35: =IF(G35>0,1,0) -> 1 | M35: =IF(I35>0,1,0) -> 1 | N35: =IF(K35>0,1,0) -> 1 | O35: =IF(OR(L35=1,M35=1,N35=1),1,0) -> 1 | P35: =IF(O35=0,"Uncovered",_xlfn.TEXTJOIN(" + ",TRUE,IF(L35=1,"UC",""),IF(M35=1,"BR",""),IF(N35=1,"WF",""))) -> UC + BR + WF
A36: HM-FR-035 | B36: 3.5 | C36: Constraint | D36: System | E36: System tracks complaint history and resolution status for review and reporting. | F36: HM-UC-009 | G36: 1 | I36: 0 | J36: HM-WF-102 | K36: 1 | L36: =IF(G36>0,1,0) -> 1 | M36: =IF(I36>0,1,0) -> 0 | N36: =IF(K36>0,1,0) -> 1 | O36: =IF(OR(L36=1,M36=1,N36=1),1,0) -> 1 | P36: =IF(O36=0,"Uncovered",_xlfn.TEXTJOIN(" + ",TRUE,IF(L36=1,"UC",""),IF(M36=1,"BR",""),IF(N36=1,"WF",""))) -> UC + WF
A37: HM-FR-036 | B37: 3.6 | C37: Interaction | D37: Student | E37: Student submits guest room booking request through the system. | F37: HM-UC-036 | G37: 1 | H37: BR-HM-051, BR-HM-052, BR-HM-053, BR-HM-054, BR-HM-055 | I37: 5 | J37: HM-WF-112 | K37: 1 | L37: =IF(G37>0,1,0) -> 1 | M37: =IF(I37>0,1,0) -> 1 | N37: =IF(K37>0,1,0) -> 1 | O37: =IF(OR(L37=1,M37=1,N37=1),1,0) -> 1 | P37: =IF(O37=0,"Uncovered",_xlfn.TEXTJOIN(" + ",TRUE,IF(L37=1,"UC",""),IF(M37=1,"BR",""),IF(N37=1,"WF",""))) -> UC + BR + WF
A38: HM-FR-037 | B38: 3.6 | C38: Constraint | D38: System | E38: System checks guest room availability before booking approval decision is recorded. | F38: HM-UC-036 | G38: 1 | I38: 0 | J38: HM-WF-112 | K38: 1 | L38: =IF(G38>0,1,0) -> 1 | M38: =IF(I38>0,1,0) -> 0 | N38: =IF(K38>0,1,0) -> 1 | O38: =IF(OR(L38=1,M38=1,N38=1),1,0) -> 1 | P38: =IF(O38=0,"Uncovered",_xlfn.TEXTJOIN(" + ",TRUE,IF(L38=1,"UC",""),IF(M38=1,"BR",""),IF(N38=1,"WF",""))) -> UC + WF
A39: HM-FR-038 | B39: 3.6 | C39: Interaction | D39: Caretaker | E39: Caretaker approves guest room booking request within authorized scope. | F39: HM-UC-037 | G39: 1 | H39: BR-HM-051 | I39: 1 | J39: HM-WF-112 | K39: 1 | L39: =IF(G39>0,1,0) -> 1 | M39: =IF(I39>0,1,0) -> 1 | N39: =IF(K39>0,1,0) -> 1 | O39: =IF(OR(L39=1,M39=1,N39=1),1,0) -> 1 | P39: =IF(O39=0,"Uncovered",_xlfn.TEXTJOIN(" + ",TRUE,IF(L39=1,"UC",""),IF(M39=1,"BR",""),IF(N39=1,"WF",""))) -> UC + BR + WF
A40: HM-FR-039 | B40: 3.6 | C40: Interaction | D40: Caretaker | E40: Caretaker rejects guest room booking request within authorized scope. | F40: HM-UC-037 | G40: 1 | H40: BR-HM-051 | I40: 1 | J40: HM-WF-112 | K40: 1 | L40: =IF(G40>0,1,0) -> 1 | M40: =IF(I40>0,1,0) -> 1 | N40: =IF(K40>0,1,0) -> 1 | O40: =IF(OR(L40=1,M40=1,N40=1),1,0) -> 1 | P40: =IF(O40=0,"Uncovered",_xlfn.TEXTJOIN(" + ",TRUE,IF(L40=1,"UC",""),IF(M40=1,"BR",""),IF(N40=1,"WF",""))) -> UC + BR + WF
...

Sheet Summary
A1: Counts and Coverage Summary
A3: Headline counts | D3: Coverage percentages | G3: Interpretive note
A4: Baseline FR count | B4: =COUNTA(FR_Coverage_Detail!A2:A2000) -> 91 | D4: UC coverage | E4: =B8/B4 -> 0.96703297 | G4: Use Cases and Workflows carry most baseline FR coverage; Business Rules cover the policy-bearing subset. Overall triad coverage is complete after repair.
A5: Final UC count | B5: =COUNTA(#REF!) -> 1 | D5: BR coverage | E5: =B9/B4 -> 0.68131868
A6: Final BR count | B6: =COUNTA(#REF!) -> 1 | D6: WF coverage | E6: =B10/B4 -> 0.92307692
A7: Final WF count | B7: =COUNTA(#REF!) -> 1 | D7: Overall triad coverage | E7: =B11/B4 -> 1
A8: FRs mapped to at least one UC | B8: =SUM(FR_Coverage_Detail!L2:L2000) -> 88
A9: FRs mapped to at least one BR | B9: =SUM(FR_Coverage_Detail!M2:M2000) -> 62
A10: FRs mapped to at least one WF | B10: =SUM(FR_Coverage_Detail!N2:N2000) -> 84
A11: FRs mapped to at least one artifact | B11: =SUM(FR_Coverage_Detail!O2:O2000) -> 91
A12: Uncovered FRs | B12: =B4-B11 -> 0
A15: Artifact-wise FR coverage
A16: UC | B16: =B8 -> 88
A17: BR | B17: =B9 -> 62
A18: WF | B18: =B10 -> 84
